Workbook

Sheet Instrukcja
A2: Prognozowanie ekonometryczne • laboratorium 1
A4: WERSJA DLA STUDENTÓW — uzupełnij żółte pola i zapisz własne wnioski.
A6: Dwa przedsiębiorstwa, miesięczne dane 01.2024–12.2025. W chwili prognozowania jest 31.12.2025. Prognozy dotyczą 01–03.2026.
A8: Najpierw wykonaj prognozy i przedziały. Dopiero potem otwórz arkusz Realizacje i oceń błędy ex post. Nie dopisuj tych wartości do próby estymacyjnej.
A10: Trend: sprzedaż firmy serwisowej, tys. zł w cenach stałych 2025 r. Koszty: zakład opakowań, tys. zł w cenach stałych 2025 r.
A12: Model kosztów wykorzystuje plan produkcji i zaplanowane godziny pracy linii. Przyjmujemy, że plany są znane i zostaną wykonane. Przedziały są warunkowe względem tych planów.
A14: Obliczenia: n = liczba obserwacji, p = liczba wszystkich parametrów, s = odchylenie standardowe reszt, m* = błąd prognozy ex ante. Poziom przedziału: 95%.
A16: Dla nowej obserwacji m* = s·√(1 + x*′(X′X)⁻¹x*). Dla średniej pomijamy 1. Przedział: y* ± t(1−α/2,n−p)·m*.
A18: Żółty: obliczenia studenta. Niebieski: dane i założenia. Biały: opis. Formuły wersji prowadzącego pozostają edytowalne.
A20: Wszystkie dane są syntetyczne, przygotowane do ćwiczeń. Nie opisują rzeczywistych przedsiębiorstw. Założono stabilne relacje, brak sezonowości oraz niezależne błędy o stałej wariancji.
A22: Zapisuj formuły, nie tylko wyniki. Nie zaokrąglaj wartości pośrednich. Znak błędu ex post: e = y − y*.
A24: W Excelu można użyć Dane > Analiza danych > Regresja albo funkcji regresji. W zadaniu Koszty sprawdź współczynniki metodą macierzową. Wektor parametrów ma kolejność: stała, produkcja, godziny.
... A30: Przydatne funkcje: SUMA, ŚREDNIA, SUMA.ILOCZYNÓW, PIERWIASTEK, LN, EXP, NACHYLENIE, ODCIĘTA. Formuły w pliku Excel wyświetla w języku instalacji.

Sheet Trend
A1: 1. Trend sprzedaży firmy serwisowej
A2: Model: Y_t = β0 + β1·t + ε_t. Sprzedaż w tys. zł, ceny stałe 2025 r.
A3: Dane syntetyczne. Estymacja: 24 miesiące 01.2024–12.2025. Moment prognozy: 31.12.2025. Nie używaj realizacji z 2026 r.
A4: 1. Przyjmij t=1 dla 01.2024. Oszacuj parametry, oblicz dopasowanie, reszty, SSE, s i R².
A5: 2. Oblicz trzy prognozy, m*, przedziały 95% i względny błąd. Oceń dopuszczalność przy progu 5%.
A6: 3. Po zapisaniu prognoz użyj arkusza Realizacje. Oblicz błędy ex post i sprawdź, czy realizacje należą do przedziałów.
A7: Wzór: m*=s·√[1+1/n+(t*−średnia t)²/Sxx]. Przedział dla średniej wykorzystuje s·√[1/n+(t*−średnia t)²/Sxx].
A8: Miesiąc | B8: t | C8: Y (tys. zł) | D8: Y dopasowane | E8: Reszta | F8: Reszta²
A9: 45292 | B9: 1 | C9: 197.8 | D9: =$I$11+B9*$I$12 -> 189.5982 | E9: =C9-D9 -> 8.2018 | F9: =E9^2 -> 67.269523 | H9: n | I9: =COUNT(B9:B32) -> 24 | J9: Liczba obserwacji estymacyjnych | L9: REGLINP:
A10: 45323 | B10: 2 | C10: 204.24 | D10: =$I$11+B10*$I$12 -> 193.60097 | E10: =C10-D10 -> 10.639035 | F10: =E10^2 -> 113.18906 | H10: p | I10: 2 | J10: Stała i jeden regresor | L10: b1(współczynnik keirunkowy) | M10: b0(wyraz wolny)
A11: 45352 | B11: 3 | C11: 202.29 | D11: =$I$11+B11*$I$12 -> 197.60373 | E11: =C11-D11 -> 4.6862696 | F11: =E11^2 -> 21.961122 | H11: b0 | I11: =INTERCEPT(C9:C32,B9:B32) -> 185.59543 | J11: Wyraz wolny modelu | K11: b1 | L11: {=LINEST(C9:C32,B9:B32,TRUE,TRUE)} -> 4.0027652 | M11: 185.59543 | N11: b0
A12: 45383 | B12: 4 | C12: 184.1 | D12: =$I$11+B12*$I$12 -> 201.6065 | E12: =C12-D12 -> -17.506496 | F12: =E12^2 -> 306.47739 | H12: b1 | I12: =SLOPE(C9:C32,B9:B32) -> 4.0027652 | J12: Współczynnik przy t | K12: SE | L12: 0.23945023 | M12: 3.4214301 | N12: SE
A13: 45413 | B13: 5 | C13: 204.11 | D13: =$I$11+B13*$I$12 -> 205.60926 | E13: =C13-D13 -> -1.4992609 | F13: =E13^2 -> 2.2477832 | H13: SSE | I13: =SUM(F9:F32) -> 1450.6112 | J13: Suma kwadratów reszt | K13: r^2 | L13: 0.92701717 | M13: 8.1201523 | N13: S reszt
A14: 45444 | B14: 6 | C14: 205.09 | D14: =$I$11+B14*$I$12 -> 209.61203 | E14: =C14-D14 -> -4.5220261 | F14: =E14^2 -> 20.44872 | H14: s | I14: =SQRT(I13/(I9-I10)) -> 8.1201523 | J14: Odchylenie standardowe reszt | K14: F | L14: 279.44074 | M14: 22 | N14: n-p(stopnie swobody)
A15: 45474 | B15: 7 | C15: 216.03 | D15: =$I$11+B15*$I$12 -> 213.61479 | E15: =C15-D15 -> 2.4152087 | F15: =E15^2 -> 5.833233 | H15: średnia y | I15: =AVERAGE(C9:C32) -> 235.63 | J15: Średnia y | K15: regresyjna suma kwadratów SSR ( suma kwadratów taka jak ogólna ale dl atych z daszkiem | L15: 18425.449 | M15: 1450.6112 | N15: SSE(suma kwadratów reszt chyba)
A16: 45505 | B16: 8 | C16: 217.47 | D16: =$I$11+B16*$I$12 -> 217.61756 | E16: =C16-D16 -> -0.14755652 | F16: =E16^2 -> 0.021772927 | H16: SS of y | I16: {=SUMSQ(C9:C32-$I$15)} -> 19876.06 | J16: Suma (t−średnia t)² | K16: SS of T( sama dopisałam) Ogólna suma kwadratów | L16: =SUM(L15+M15) -> 19876.06
A17: 45536 | B17: 9 | C17: 210.03 | D17: =$I$11+B17*$I$12 -> 221.62032 | E17: =C17-D17 -> -11.590322 | F17: =E17^2 -> 134.33556 | H17: kwantyl t | I17: =N19 -> 2.0738731 | J17: Dwustronny przedział 95%
A18: 45566 | B18: 10 | C18: 226.18 | D18: =$I$11+B18*$I$12 -> 225.62309 | E18: =C18-D18 -> 0.55691304 | F18: =E18^2 -> 0.31015214 | H18: R² | I18: =L15/L16 -> 0.92701717 | J18: Dopasowanie w skali modelu | L18: t1 | M18: t0 | N18: t krytyczne
A19: 45597 | B19: 11 | C19: 227.43 | D19: =$I$11+B19*$I$12 -> 229.62585 | E19: =C19-D19 -> -2.1958522 | F19: =E19^2 -> 4.8217668 | H19: α | I19: 0.05 | J19: Poziom istotności | L19: =ABS(L11/L12) -> 16.716481 | M19: =ABS(M11/M12) -> 54.244988 | N19: =_xlfn.T.INV.2T(I19,$M$14) -> 2.0738731 | O19: t1,t0 >t krytyczne- należy odrzucić h0. Parametry są istotne statystycznie
A20: 45627 | B20: 12 | C20: 233.6 | D20: =$I$11+B20*$I$12 -> 233.62862 | E20: =C20-D20 -> -0.028617391 | F20: =E20^2 -> 0.00081895509 | H20: próg względny | I20: 0.05 | J20: Dotyczy zadania Trend | K20: p-value | L20: =_xlfn.T.DIST.2T(L19,$M$14) -> 5.4483526e-14 | M20: =_xlfn.T.DIST.2T(M19,$M$14) -> 6.3449889e-25
A21: 45658 | B21: 13 | C21: 243.96 | D21: =$I$11+B21*$I$12 -> 237.63138 | E21: =C21-D21 -> 6.3286174 | F21: =E21^2 -> 40.051398 | L21: <0,05 | M21: <0,05
A22: 45689 | B22: 14 | C22: 246.8 | D22: =$I$11+B22*$I$12 -> 241.63415 | E22: =C22-D22 -> 5.1658522 | F22: =E22^2 -> 26.686029 | H22: R^2 | I22: =RSQ(C9:C32,B9:B32) -> 0.92701717 | L22: należy odrzucić ho-parametr jest istotny statystycznie
A23: 45717 | B23: 15 | C23: 246.62 | D23: =$I$11+B23*$I$12 -> 245.63691 | E23: =C23-D23 -> 0.98308696 | F23: =E23^2 -> 0.96645996
A24: 45748 | B24: 16 | C24: 237.13 | D24: =$I$11+B24*$I$12 -> 249.63968 | E24: =C24-D24 -> -12.509678 | F24: =E24^2 -> 156.49205 | H24: Średnia t | I24: =AVERAGE(B9:B32) -> 12.5
A25: 45778 | B25: 17 | C25: 254.84 | D25: =$I$11+B25*$I$12 -> 253.64244 | E25: =C25-D25 -> 1.1975565 | F25: =E25^2 -> 1.4341416 | H25: SS of T | I25: =_xlfn.STDEV.P(B9:B32) -> 6.9221866
A26: 45809 | B26: 18 | C26: 267.02 | D26: =$I$11+B26*$I$12 -> 257.64521 | E26: =C26-D26 -> 9.3747913 | F26: =E26^2 -> 87.886712 | H26: St | I26: {=SUMSQ(B9:B32-$I$24)} -> 1150
A27: 45839 | B27: 19 | C27: 249.6 | D27: =$I$11+B27*$I$12 -> 261.64797 | E27: =C27-D27 -> -12.047974 | F27: =E27^2 -> 145.15368
A28: 45870 | B28: 20 | C28: 272.67 | D28: =$I$11+B28*$I$12 -> 265.65074 | E28: =C28-D28 -> 7.0192609 | F28: =E28^2 -> 49.270023
A29: 45901 | B29: 21 | C29: 284.7 | D29: =$I$11+B29*$I$12 -> 269.6535 | E29: =C29-D29 -> 15.046496 | F29: =E29^2 -> 226.39703
A30: 45931 | B30: 22 | C30: 269.87 | D30: =$I$11+B30*$I$12 -> 273.65627 | E30: =C30-D30 -> -3.7862696 | F30: =E30^2 -> 14.335837
A31: 45962 | B31: 23 | C31: 272.73 | D31: =$I$11+B31*$I$12 -> 277.65903 | E31: =C31-D31 -> -4.9290348 | F31: =E31^2 -> 24.295384 | H31: y* | I31: wartość oczekiwana zmiennej losowe-możliwe przysżłe wartości y
A32: 45992 | B32: 24 | C32: 280.81 | D32: =$I$11+B32*$I$12 -> 281.6618 | E32: =C32-D32 -> -0.8518 | F32: =E32^2 -> 0.72556324 | H32: m* | I32: odchylenie standardowe zmiennej losowej czyli y*
E33: =SUM(E9:E32) -> 2.5579538e-13 | H33: m* średniej | I33: odchylenie standardowe zmiennej losowe średnia wartość y a średnia wartość to zmienna losowa o rozkładzie normalnym
D34: Ocena niepewności z jaką my podajemy tą prognozę | H34: Jakbyśmy zrobili śrendia prognozę to jej odchylenie wynosiłoby tyle
D35: tutat ta jedynka dlatego że mam jeszcze jednego epsilona więcej i on nie jest uwględniony w parametrach regresji | H35: tak wyglądałby błąd gdyby nie było w przyszłości żadnej dodatkowej losowości | I35: skopiowane z REALIZACJE | J35: RMSE | L35: Tak bo m*|y| mniejsze niż 5% czyli podany próg dopuszcalności
A36: Miesiąc | B36: t* | C36: y* | D36: m* | E36: Dolna 95% | F36: Górna 95% | G36: m*/|y*| | H36: m* średniej | I36: Realizacja | J36: Błąd ex post | K36: W przedziale? | L36: Dopuszczalna?
A37: 46023 | B37: 25 | C37: =B37*$I$12+$I$11 -> 285.66457 | D37: =$I$14*SQRT(1+1/$I$9+(B37-$I$24)^2/$I$26) -> 8.8115298 | E37: =C37-D37*$I$17 -> 267.39057 | F37: =C37+D37*$I$17 -> 303.93856 | G37: =D37/ABS(C37) -> 0.030845722 | H37: =$I$14*SQRT(1/$I$9+(B37-$I$24)^2/$I$26) -> 3.4214301 | I37: =Realizacje!B7 -> 269.48 | J37: =I37-C37 -> -16.184565 | K37: TAK | L37: TAK
A38: 46054 | B38: 26 | C38: =B38*$I$12+$I$11 -> 289.66733 | D38: =$I$14*SQRT(1+1/$I$9+(B38-$I$24)^2/$I$26) -> 8.8957183 | E38: =C38-D38*$I$17 -> 271.21874 | F38: =C38+D38*$I$17 -> 308.11592 | G38: =D38/ABS(C38) -> 0.030710119 | H38: =$I$14*SQRT(1/$I$9+(B38-$I$24)^2/$I$26) -> 3.632758 | I38: =Realizacje!B8 -> 311.17 | J38: =I38-C38 -> 21.50267 | K38: NIE | L38: TAK
A39: 46082 | B39: 27 | C39: =B39*$I$12+$I$11 -> 293.6701 | D39: =$I$14*SQRT(1+1/$I$9+(B39-$I$24)^2/$I$26) -> 8.9855007 | E39: =C39-D39*$I$17 -> 275.03531 | F39: =C39+D39*$I$17 -> 312.30488 | G39: =D39/ABS(C39) -> 0.030597262 | H39: =$I$14*SQRT(1/$I$9+(B39-$I$24)^2/$I$26) -> 3.8473823 | I39: =Realizacje!B9 -> 288.11 | J39: =I39-C39 -> -5.5600957 | K39: TAK | L39: TAK
D40: błąd systematrycznie rośnie i tak powinno być. Mówi z jaką niep[ewnością | G40: wszytskie są dopuszczalne bo mamy 5% poziom dopuszczalności (próg względny) | J40: Ocena po fakcie
...

Sheet Koszty
A1: 2. Prognoza kosztów zakładu opakowań
A2: Y: koszty (tys. zł, ceny 2025 r.), X1: produkcja (tys. sztuk), X2: godziny pracy linii. Dane syntetyczne.
A3: Estymacja: 01.2024–12.2025. Prognozy na 01–03.2026 sporządzamy 31.12.2025 przy znanym planie X1 i X2.
A4: 1. Oszacuj Y=β0+β1X1+β2X2+ε. Zbuduj X′X, X′Y i (X′X)⁻¹. Kolejność kolumn X: 1, X1, X2.
A5: 2. Oblicz b=(X′X)⁻¹X′Y, reszty, SSE, s, R² oraz prognozy, m* i przedziały 95%. Porównaj z raportem Regresja.
A6: 3. Oceń dopuszczalność przy progu 5%. Uzupełnij e=y−y* dopiero po otwarciu Realizacje. Wskaż, czego nie obejmuje warunkowy przedział.
A7: Macierze: MACIERZ.ODW (MINVERSE), MACIERZ.ILOCZYN (MMULT). W Excelu 365 wynik może się rozlać. W starszym Excelu zaznacz blok i zatwierdź Ctrl+Shift+Enter.
A8: Miesiąc | B8: constant | C8: X1 | D8: X2 | E8: Y | F8: Y dopasowane | G8: Reszta | H8: Reszta² | I8: Y dopasowane inna funkcja (rglinw z ctrl+shift+enter
A9: 45292 | B9: 1 | C9: 139.3 | D9: 115 | E9: 333.59 | F9: =$M$9+$M$10*C9+$M$11*D9 -> 335.95678 | G9: {=E9:E32-F9:F32} -> -2.3667808 | H9: {=G9:G32^2} -> 5.6016515 | I9: {=TREND(E9:E32,C9:D32,C9:D32,TRUE)} -> 335.95678 | L9: b0 | M9: =Q14 -> 62.16139
A10: 45323 | B10: 1 | C10: 73 | D10: 136 | E10: 237.38 | F10: =$M$9+$M$10*C10+$M$11*D10 -> 232.01953 | G10: 5.360468 | H10: 28.734617 | I10: 232.01953 | L10: b1 | M10: =P14 -> 1.6779926
A11: 45352 | B11: 1 | C11: 81.4 | D11: 138 | E11: 254.78 | F11: =$M$9+$M$10*C11+$M$11*D11 -> 246.81121 | G11: 7.9687904 | H11: 63.50162 | I11: 246.81121 | L11: b2 | M11: =O14 -> 0.3482697
A12: 45383 | B12: 1 | C12: 118.6 | D12: 142 | E12: 302.45 | F12: =$M$9+$M$10*C12+$M$11*D12 -> 310.62561 | G12: -8.1756149 | H12: 66.840678 | I12: 310.62561 | L12: n | M12: =P17+3 -> 24
A13: 45413 | B13: 1 | C13: 95.7 | D13: 114 | E13: 255.56 | F13: =$M$9+$M$10*C13+$M$11*D13 -> 262.44803 | G13: -6.8880318 | H13: 47.444981 | I13: 262.44803 | L13: p | M13: 3 | O13: b2 | P13: b1 | Q13: b0
A14: 45444 | B14: 1 | C14: 72.6 | D14: 131 | E14: 218.89 | F14: =$M$9+$M$10*C14+$M$11*D14 -> 229.60699 | G14: -10.716986 | H14: 114.8538 | I14: 229.60699 | L14: SSE | M14: =P18 -> 970.71278 | O14: {=LINEST(E9:E32,C9:D32,TRUE,TRUE)} -> 0.3482697 | P14: 1.6779926 | Q14: 62.16139
A15: 45474 | B15: 1 | C15: 85.9 | D15: 167 | E15: 268.56 | F15: =$M$9+$M$10*C15+$M$11*D15 -> 264.462 | G15: 4.0980023 | H15: 16.793622 | I15: 264.462 | L15: s | M15: =P16 -> 6.7988542 | O15: 0.051940119 | P15: 0.0716723 | Q15: 10.417213
A16: 45505 | B16: 1 | C16: 86 | D16: 185 | E16: 270.9 | F16: =$M$9+$M$10*C16+$M$11*D16 -> 270.89865 | G16: 0.0013484502 | H16: 1.818318e-06 | I16: 270.89865 | L16: R² | M16: =O16 -> 0.96629585 | O16: 0.96629585 | P16: 6.7988542 | Q16: #N/A
A17: 45536 | B17: 1 | C17: 127 | D17: 191 | E17: 340.01 | F17: =$M$9+$M$10*C17+$M$11*D17 -> 341.78597 | G17: -1.7759682 | H17: 3.1540632 | I17: 341.78597 | L17: α | M17: 0.05 | O17: 301.03435 | P17: 21 | Q17: #N/A
A18: 45566 | B18: 1 | C18: 102.8 | D18: 184 | E18: 303.77 | F18: =$M$9+$M$10*C18+$M$11*D18 -> 298.74066 | G18: 5.0293417 | H18: 25.294278 | I18: 298.74066 | L18: kwantyl t | M18: =_xlfn.T.INV.2T(M17,P17) -> 2.0796138 | O18: 27830.275 | P18: 970.71278 | Q18: #N/A
A19: 45597 | B19: 1 | C19: 83.4 | D19: 126 | E19: 249.21 | F19: =$M$9+$M$10*C19+$M$11*D19 -> 245.98796 | G19: 3.2220414 | H19: 10.381551 | I19: 245.98796 | L19: próg względny | M19: 0.05
A20: 45627 | B20: 1 | C20: 79.6 | D20: 124 | E20: 232.69 | F20: =$M$9+$M$10*C20+$M$11*D20 -> 238.91505 | G20: -6.2250471 | H20: 38.751212 | I20: 238.91505
A21: 45658 | B21: 1 | C21: 79.1 | D21: 128 | E21: 246.47 | F21: =$M$9+$M$10*C21+$M$11*D21 -> 239.46913 | G21: 7.0008704 | H21: 49.012187 | I21: 239.46913
A22: 45689 | B22: 1 | C22: 82.9 | D22: 146 | E22: 250.93 | F22: =$M$9+$M$10*C22+$M$11*D22 -> 252.11436 | G22: -1.1843562 | H22: 1.4026996 | I22: 252.11436
A23: 45717 | B23: 1 | C23: 81.6 | D23: 166 | E23: 251.46 | F23: =$M$9+$M$10*C23+$M$11*D23 -> 256.89836 | G23: -5.4383597 | H23: 29.575756 | I23: 256.89836
A24: 45748 | B24: 1 | C24: 79.1 | D24: 181 | E24: 257.29 | F24: =$M$9+$M$10*C24+$M$11*D24 -> 257.92742 | G24: -0.6374235 | H24: 0.40630872 | I24: 257.92742
A25: 45778 | B25: 1 | C25: 125.5 | D25: 186 | E25: 334.92 | F25: =$M$9+$M$10*C25+$M$11*D25 -> 337.52763 | G25: -2.6076308 | H25: 6.7997383 | I25: 337.52763
A26: 45809 | B26: 1 | C26: 86.6 | D26: 165 | E26: 249.17 | F26: =$M$9+$M$10*C26+$M$11*D26 -> 264.94005 | G26: -15.770053 | H26: 248.69458 | I26: 264.94005
A27: 45839 | B27: 1 | C27: 82.4 | D27: 191 | E27: 274.85 | F27: =$M$9+$M$10*C27+$M$11*D27 -> 266.9475 | G27: 7.9025038 | H27: 62.449566 | I27: 266.9475
A28: 45870 | B28: 1 | C28: 105.5 | D28: 131 | E28: 289.02 | F28: =$M$9+$M$10*C28+$M$11*D28 -> 284.81294 | G28: 4.2070555 | H28: 17.699316 | I28: 284.81294
A29: 45901 | B29: 1 | C29: 122.1 | D29: 134 | E29: 313.96 | F29: =$M$9+$M$10*C29+$M$11*D29 -> 313.71243 | G29: 0.24756844 | H29: 0.061290135 | I29: 313.71243
A30: 45931 | B30: 1 | C30: 121.7 | D30: 138 | E30: 323.37 | F30: =$M$9+$M$10*C30+$M$11*D30 -> 314.43431 | G30: 8.9356867 | H30: 79.846497 | I30: 314.43431
A31: 45962 | B31: 1 | C31: 101.8 | D31: 116 | E31: 280.67 | F31: =$M$9+$M$10*C31+$M$11*D31 -> 273.38033 | G31: 7.2896737 | H31: 53.139343 | I31: 273.38033
A32: 45992 | B32: 1 | C32: 108.1 | D32: 188 | E32: 309.55 | F32: =$M$9+$M$10*C32+$M$11*D32 -> 309.0271 | G32: 0.52290187 | H32: 0.27342637 | I32: 309.0271
H33: =SUM(H9:H32) -> 970.71278
A35: X′X (1, X1, X2) | F35: (X′X)⁻¹ | J35: X′Y
A37: {=MMULT(TRANSPOSE(B9:D32),B9:D32)} -> 24 | B37: 2321.7 | C37: 3623 | F37: {=MINVERSE(_xlfn.ANCHORARRAY(A37))} -> 2.3476408 | G37: -0.010419712 | H37: -0.008598381 | J37: {=MMULT(TRANSPOSE(B9:D32),E9:E32)} -> 6649.45
A38: 2321.7 | B38: 233600.59 | C38: 350818 | F38: -0.010419712 | G38: 0.00011112998 | H38: -2.1908317e-06 | J38: 658479.45
A39: 3623 | B39: 350818 | C39: 564069 | F39: -0.008598381 | G39: -2.1908317e-06 | H39: 5.8362572e-05 | J39: 1010328.9
B43: MACIERZ x* | F43: x* to są x1 i x2 te w prżód
A44: Miesiąc | B44: constant | C44: Plan X1 | D44: Plan X2 | E44: y* | F44: h=x*′(X′X)⁻¹x* | G44: m* | H44: Dolna 95% | I44: Górna 95% | J44: m*/|y*| | K44: Realizacja | L44: e=y−y* | M44: Dopuszczalna?
A45: 46023 | B45: 1 | C45: 80.2 | D45: 197 | E45: =$M$9+$M$10*C45+D45*$M$11 -> 265.34553 | F45: {=MMULT(MMULT(B45:D45,_xlfn.ANCHORARRAY($F$37)),TRANSPOSE(B45:D45))} -> 0.19911477 | G45: =$M$15*SQRT(1+F45) -> 7.445024 | H45: =E45-G45 -> 257.90051 | I45: =E45+G45 -> 272.79055 | J45: =G45/ABS(E45) -> 0.028057846 | K45: =Realizacje!C7 -> 263.27 | L45: =K45-E45 -> -2.0755306 | M45: TAK
...

Sheet Realizacje
A2: Realizacje poznane po okresie prognozy
A4: Otwórz dopiero po obliczeniu i zapisaniu prognoz. Te wartości nie mogą wejść do estymacji modeli miesięcznych.
A6: Miesiąc | B6: Sprzedaż (tys. zł) | C6: Koszty (tys. zł)
A7: 46023 | B7: 269.48 | C7: 263.27
A8: 46054 | B8: 311.17 | C8: 303.15
A9: 46082 | B9: 288.11 | C9: 309.02
A12: Dane syntetyczne. Wyniki są dostępne wyłącznie do oceny ex post, po zakończeniu odpowiedniego miesiąca.
