Workbook

Sheet Instrukcja
A1: Prognozowanie ekonometryczne • laboratorium 2
A2: WERSJA DLA STUDENTÓW — uzupełnij żółte pola i zapisz własne wnioski.
A3: Wykladniczy i Potegowy: estymacja 01.2024–12.2025, prognozy na 01–03.2026 sporządzone 31.12.2025. Dla modelu potęgowego plan produkcji jest znany z góry.
A4: Najpierw prognozujemy logarytm Y. Potem obliczamy medianę exp(μ*), przybliżoną średnią exp(μ* + v/2) oraz granice przedziału przez potęgowanie granic w logach.
A5: Wariancja v = [m*(log)]². Korekta średniej jest normalnym przybliżeniem pełnego rozkładu prognostycznego. Przedział w logach wykorzystuje kwantyl t, a nie automatycznie 1,96.
A6: Przy modelu potęgowym błędy i odległości obliczamy dla ln(X), nie dla X. Parametr β jest elastycznością bez znaku %. Wzrost X o 1% daje około β% zmiany części systematycznej Y.
A7: CW: syntetyczna sprzedaż tygodniowa sklepu internetowego i budżet reklamy ustalony przed tygodniem. M0 jest liniowy, M1 zawiera dodatkowo kwadrat budżetu.
A8: Pierwsze 36 tygodni służy do estymacji. Kolejnych 60 prognoz powstaje na jeden tydzień naprzód. Przed każdym tygodniem modele są ponownie szacowane wyłącznie na wcześniejszych obserwacjach.
A9: W CW dostajesz gotowe prognozy M0 i M1. Uzupełnij błędy, kwadraty, korektę i d. Historia i wzory estymacji są w arkuszu Modele_CW, który można przejrzeć po wykonaniu zadania.
A10: Podstawowa wersja: SE(d̄) = s_d/√P, CW = d̄/SE(d̄), p ≈ 1−Φ(CW). s_d to odchylenie standardowe wartości d, nie ich średnich. Nie stosujemy HAC.
A11: Przyjmujemy brak istotnej zależności czasowej d. Sam horyzont h=1 tego nie gwarantuje. Wynik jest dydaktycznym przybliżeniem, a nie uniwersalną procedurą dla dowolnego szeregu.
A12: Wszystkie dane są syntetyczne. Żółty: pola do obliczeń. Niebieski: dane. Arkusz Realizacje otwórz dopiero po zapisaniu prognoz miesięcznych.
... A17: Przydatne funkcje: SUMA, ŚREDNIA, SUMA.ILOCZYNÓW, PIERWIASTEK, LN, EXP, NACHYLENIE, ODCIĘTA. Formuły w pliku Excel wyświetla w języku instalacji.

Sheet Wykladniczy
A1: 1. Abonenci usługi B2B: trend wykładniczy
A2: Model: Y_t = exp(α + β·t + u_t). Y: liczba aktywnych abonentów na koniec miesiąca.
A3: Dane syntetyczne. Estymacja: 24 miesiące 01.2024–12.2025. Moment prognozy: 31.12.2025. Nie używaj realizacji z 2026 r.
A4: 1. Przyjmij t=1 dla 01.2024. Oszacuj parametry, oblicz dopasowanie, reszty, SSE, s i R².
A5: 2. Oblicz μ*, m*(log), medianę i średnią Y. Przyjmij v=[m*(log)]². Wyznacz przedział w logach i potęguj obie granice.
A6: 3. Po zapisaniu prognoz użyj arkusza Realizacje. Oblicz błędy ex post i sprawdź, czy realizacje należą do przedziałów.
A7: Wzór: m*(log)=s·√[1+1/n+(z*−średnia z)²/Szz]. Dla trendu z=t, dla modelu potęgowego z=ln(X).
A8: Miesiąc | B8: t | C8: Y (osoby) | D8: Z modelu | E8: W modelu | F8: W dopasowane | G8: Reszta | H8: Reszta²
A9: 45292 | B9: 1 | C9: 1317 | D9: =B9 -> 1 | E9: =LN(C9) -> 7.1831117 | F9: {=TREND(E9:E32,D9:D32,D9:D32,TRUE)} -> 7.1399933 | G9: =E9-F9 -> 0.043118416 | H9: =G9^2 -> 0.0018591978 | J9: n | K9: =COUNT(B9:B32) -> 24 | L9: Liczba obserwacji estymacyjnych
A10: 45323 | B10: 2 | C10: 1330 | D10: =B10 -> 2 | E10: =LN(C10) -> 7.1929342 | F10: 7.1688159 | G10: =E10-F10 -> 0.024118332 | H10: =G10^2 -> 0.00058169392 | J10: p | K10: 2 | L10: Stała i jeden regresor
A11: 45352 | B11: 3 | C11: 1311 | D11: =B11 -> 3 | E11: =LN(C11) -> 7.1785455 | F11: 7.1976385 | G11: =E11-F11 -> -0.01909301 | H11: =G11^2 -> 0.00036454303 | J11: b0 | K11: =INTERCEPT(E9:E32,D9:D32) -> 7.1111707 | L11: Wyraz wolny modelu pomocniczego
A12: 45383 | B12: 4 | C12: 1365 | D12: =B12 -> 4 | E12: =LN(C12) -> 7.2189097 | F12: 7.2264611 | G12: =E12-F12 -> -0.0075513904 | H12: =G12^2 -> 5.7023497e-05 | J12: b1 | K12: =SLOPE(E9:E32,D9:D32) -> 0.028822604 | L12: Współczynnik przy z | N12: {=LINEST(D9:D32,E9:E32,TRUE,TRUE)} -> 34.009977 | O12: -241.60395
A13: 45413 | B13: 5 | C13: 1467 | D13: =B13 -> 5 | E13: =LN(C13) -> 7.2909748 | F13: 7.2552837 | G13: =E13-F13 -> 0.035691076 | H13: =G13^2 -> 0.0012738529 | J13: SSE | K13: =SUM(H9:H32) -> 0.019242321 | L13: Suma kwadratów reszt | N13: 1.0290621 | O13: 7.6913856
A14: 45444 | B14: 6 | C14: 1411 | D14: =B14 -> 6 | E14: =LN(C14) -> 7.252054 | F14: 7.2841063 | G14: =E14-F14 -> -0.032052355 | H14: =G14^2 -> 0.0010273534 | J14: s | K14: =SQRT(K13/O15) -> 0.029574499 | L14: Odchylenie standardowe reszt | N14: 0.98025611 | O14: 1.015907
A15: 45474 | B15: 7 | C15: 1446 | D15: =B15 -> 7 | E15: =LN(C15) -> 7.2765564 | F15: 7.3129289 | G15: =E15-F15 -> -0.036372508 | H15: =G15^2 -> 0.0013229593 | J15: średnia z | K15: =AVERAGE(D9:D32) -> 12.5 | L15: Średnia regresora w estymacji | N15: 1092.2687 | O15: 22
A16: 45505 | B16: 8 | C16: 1603 | D16: =B16 -> 8 | E16: =LN(C16) -> 7.3796322 | F16: 7.3417515 | G16: =E16-F16 -> 0.037880638 | H16: =G16^2 -> 0.0014349427 | J16: Szz | K16: {=SUMSQ(D9:D32-$K$15)} -> 1150 | L16: Suma (z−średnia z)² | N16: 1127.2945 | O16: 22.705475
A17: 45536 | B17: 9 | C17: 1588 | D17: =B17 -> 9 | E17: =LN(C17) -> 7.3702306 | F17: 7.3705741 | G17: =E17-F17 -> -0.00034347714 | H17: =G17^2 -> 1.1797655e-07 | J17: kwantyl t | K17: =_xlfn.T.INV.2T(K19,O15) -> 2.0738731 | L17: Dwustronny przedział 95%
A18: 45566 | B18: 10 | C18: 1591 | D18: =B18 -> 10 | E18: =LN(C18) -> 7.372118 | F18: 7.3993967 | G18: =E18-F18 -> -0.027278695 | H18: =G18^2 -> 0.00074412719 | J18: R² | K18: =RSQ(E9:E32,D9:D32) -> 0.98025611 | L18: Dopasowanie w skali modelu
A19: 45597 | B19: 11 | C19: 1618 | D19: =B19 -> 11 | E19: =LN(C19) -> 7.3889461 | F19: 7.4282193 | G19: =E19-F19 -> -0.03927323 | H19: =G19^2 -> 0.0015423866 | J19: α | K19: 0.05 | L19: Poziom istotności
A20: 45627 | B20: 12 | C20: 1744 | D20: =B20 -> 12 | E20: =LN(C20) -> 7.4639366 | F20: 7.4570419 | G20: =E20-F20 -> 0.006894673 | H20: =G20^2 -> 4.7536515e-05
A21: 45658 | B21: 13 | C21: 1852 | D21: =B21 -> 13 | E21: =LN(C21) -> 7.5240214 | F21: 7.4858645 | G21: =E21-F21 -> 0.03815688 | H21: =G21^2 -> 0.0014559475
A22: 45689 | B22: 14 | C22: 1739 | D22: =B22 -> 14 | E22: =LN(C22) -> 7.4610655 | F22: 7.5146871 | G22: =E22-F22 -> -0.053621626 | H22: =G22^2 -> 0.0028752787 | J22: Tempo miesięczne
A23: 45717 | B23: 15 | C23: 1867 | D23: =B23 -> 15 | E23: =LN(C23) -> 7.5320881 | F23: 7.5435097 | G23: =E23-F23 -> -0.011421601 | H23: =G23^2 -> 0.00013045296 | J23: Tempo przybliżone
A24: 45748 | B24: 16 | C24: 1877 | D24: =B24 -> 16 | E24: =LN(C24) -> 7.53743 | F24: 7.5723323 | G24: =E24-F24 -> -0.034902312 | H24: =G24^2 -> 0.0012181714
A25: 45778 | B25: 17 | C25: 2053 | D25: =B25 -> 17 | E25: =LN(C25) -> 7.6270574 | F25: 7.601155 | G25: =E25-F25 -> 0.025902465 | H25: =G25^2 -> 0.00067093767
A26: 45809 | B26: 18 | C26: 2089 | D26: =B26 -> 18 | E26: =LN(C26) -> 7.6444408 | F26: 7.6299776 | G26: =E26-F26 -> 0.014463205 | H26: =G26^2 -> 0.0002091843
A27: 45839 | B27: 19 | C27: 2114 | D27: =B27 -> 19 | E27: =LN(C27) -> 7.6563372 | F27: 7.6588002 | G27: =E27-F27 -> -0.0024629944 | H27: =G27^2 -> 6.0663413e-06
A28: 45870 | B28: 20 | C28: 2168 | D28: =B28 -> 20 | E28: =LN(C28) -> 7.6815604 | F28: 7.6876228 | G28: =E28-F28 -> -0.0060624024 | H28: =G28^2 -> 3.6752723e-05
A29: 45901 | B29: 21 | C29: 2225 | D29: =B29 -> 21 | E29: =LN(C29) -> 7.7075122 | F29: 7.7164454 | G29: =E29-F29 -> -0.0089331746 | H29: =G29^2 -> 7.9801608e-05
A30: 45931 | B30: 22 | C30: 2383 | D30: =B30 -> 22 | E30: =LN(C30) -> 7.7761155 | F30: 7.745268 | G30: =E30-F30 -> 0.030847504 | H30: =G30^2 -> 0.00095156849
A31: 45962 | B31: 23 | C31: 2349 | D31: =B31 -> 23 | E31: =LN(C31) -> 7.761745 | F31: 7.7740906 | G31: =E31-F31 -> -0.012345593 | H31: =G31^2 -> 0.00015241366
A32: 45992 | B32: 24 | C32: 2534 | D32: =B32 -> 24 | E32: =LN(C32) -> 7.8375544 | F32: 7.8029132 | G32: =E32-F32 -> 0.034641179 | H32: =G32^2 -> 0.0012000113 | K32: MACIERZ POMOCNICZA DO m*
L33: Z*
A34: X′X (1,Z) | E34: (X′X)⁻¹ | I34: X′Y | K34: 1 | L34: 25
A35: na piesoz liczymy bo się nie chcialo 1 dodac ale można normalnie macierzami | K35: 1 | L35: 26
A36: =COUNT(B9:B32) -> 24 | B36: =SUM(D9:D32) -> 300 | E36: {=MINVERSE(A36:B37)} -> 0.17753623 | F36: -0.010869565 | I36: =SUM(E9:E32) -> 179.31488 | K36: 1 | L36: 27
A37: =B36 -> 300 | B37: =SUMSQ(D9:D32) -> 4900 | E37: -0.010869565 | F37: 0.00086956522 | I37: =SUMPRODUCT(D9:D32,E9:E32) -> 2274.582
D38: w*-wartość oczekiwana modelu liniowego | L38: prognozy punktowe
A39: Miesiąc | B39: t* | C39: z* | D39: μ* | E39: m*(log) | F39: v | G39: Mediana Y | H39: Średnia Y | I39: Dolna 95% | J39: Górna 95% | K39: Realizacja | L39: Błąd średniej | M39: szerokość przedziału
A40: 46023 | B40: 25 | C40: =B40 -> 25 | D40: {=TREND(E9:E32,D9:D32,C40:C42,TRUE)} -> 7.8317358 | E40: {=$K$14*SQRT(1+MMULT(MMULT(K34:L34,_xlfn.ANCHORARRAY($E$36)),TRANSPOSE(K34:L34)))} -> 0.032092573 | F40: =E40^2 -> 0.0010299332 | G40: =EXP(D40) -> 2519.2985 | H40: =EXP(D40+F40/2) -> 2520.5962 | I40: =EXP(D40-$K$17*E40) -> 2357.0824 | J40: =EXP(D40+$K$17*E40) -> 2692.6785 | K40: =Realizacje!B7 -> 2504 | L40: =K40-H40 -> -16.596232 | M40: =(J40-I40)/2 -> 167.79806 | N40: =M40/K40 -> 0.067012003
...

Sheet Potegowy
A1: 2. Energia w zakładzie opakowań: model potęgowy
A2: Model: Y_t = A·X_t^β·exp(u_t). Y: energia (MWh), X: produkcja (tys. sztuk).
A3: Dane syntetyczne. Estymacja: 24 miesiące 01.2024–12.2025. Moment prognozy: 31.12.2025. Nie używaj realizacji z 2026 r.
A4: 1. Oblicz ln(X) i ln(Y), oszacuj model pomocniczy. Podaj elastyczność i ocenę A = exp(b0).
A5: 2. Oblicz μ*, m*(log), medianę i średnią Y. Przyjmij v=[m*(log)]². Wyznacz przedział w logach i potęguj obie granice.
A6: 3. Po zapisaniu prognoz użyj arkusza Realizacje. Oblicz błędy ex post i sprawdź, czy realizacje należą do przedziałów.
A7: Wzór: m*(log)=s·√[1+1/n+(z*−średnia z)²/Szz]. Dla trendu z=t, dla modelu potęgowego z=ln(X).
A8: Miesiąc | B8: X (tys. szt.) | C8: Y (MWh) | D8: Z modelu | E8: W modelu | F8: W dopasowane | G8: Reszta | H8: Reszta²
A9: 45292 | B9: 120.6 | C9: 732.9 | D9: {=LN(B9:B32)} -> 4.7924793 | E9: =LN(C9) -> 6.5970093 | F9: {=TREND(E9:E32,D9:D32,D9:D32,1)} -> 6.5493116 | G9: {=E9:E32-F9:F32} -> 0.047697681 | H9: {=G9:G32^2} -> 0.0022750688 | J9: n | K9: =COUNT(A9:A32) -> 24 | L9: Liczba obserwacji estymacyjnych
A10: 45323 | B10: 109.8 | C10: 644.6 | D10: 4.6986605 | E10: =LN(C10) -> 6.46863 | F10: 6.4837943 | G10: -0.015164294 | H10: 0.00022995581 | J10: p | K10: 2 | L10: Stała i jeden regresor
A11: 45352 | B11: 169.3 | C11: 917.9 | D11: 5.1316723 | E11: =LN(C11) -> 6.8220885 | F11: 6.7861834 | G11: 0.035905065 | H11: 0.0012891737 | J11: b0 | K11: =INTERCEPT(E9:E32,_xlfn.ANCHORARRAY(D9)) -> 3.202535 | L11: Wyraz wolny modelu pomocniczego
A12: 45383 | B12: 90 | C12: 591.5 | D12: 4.4998097 | E12: =LN(C12) -> 6.3826617 | F12: 6.3449289 | G12: 0.037732787 | H12: 0.0014237632 | J12: b1 | K12: =SLOPE(E9:E32,_xlfn.ANCHORARRAY(D9)) -> 0.69833929 | L12: Współczynnik przy z
A13: 45413 | B13: 123.9 | C13: 708.2 | D13: 4.8194748 | E13: =LN(C13) -> 6.5627265 | F13: 6.5681636 | G13: -0.0054370674 | H13: 2.9561702e-05 | J13: SSE | K13: =SUM(_xlfn.ANCHORARRAY(H9)) -> 0.034496037 | L13: Suma kwadratów reszt
A14: 45444 | B14: 90.2 | C14: 536 | D14: 4.5020294 | E14: =LN(C14) -> 6.2841342 | F14: 6.346479 | G14: -0.062344879 | H14: 0.0038868839 | J14: s | K14: =SQRT(K13/(K9-K10)) -> 0.039598001 | L14: Odchylenie standardowe reszt
A15: 45474 | B15: 117.1 | C15: 661.3 | D15: 4.7630283 | E15: =LN(C15) -> 6.4942076 | F15: 6.5287448 | G15: -0.034537191 | H15: 0.0011928176 | J15: średnia z | K15: =AVERAGE(_xlfn.ANCHORARRAY(D9)) -> 4.8073216 | L15: Średnia regresora w estymacji
A16: 45505 | B16: 89.4 | C16: 582.1 | D16: 4.4931207 | E16: =LN(C16) -> 6.3666423 | F16: 6.3402577 | G16: 0.026384541 | H16: 0.00069614401 | J16: Szz | K16: {=SUMSQ(D11:D32-$K$15)} -> 1.0035163 | L16: Suma (z−średnia z)²
A17: 45536 | B17: 132.3 | C17: 733.2 | D17: 4.8850721 | E17: =LN(C17) -> 6.5974185 | F17: 6.6139728 | G17: -0.016554251 | H17: 0.00027404321 | J17: kwantyl t | L17: Dwustronny przedział 95%
A18: 45566 | B18: 86.8 | C18: 570.5 | D18: 4.4636066 | E18: =LN(C18) -> 6.3465132 | F18: 6.3196469 | G18: 0.026866284 | H18: 0.00072179722 | J18: R² | L18: Dopasowanie w skali modelu
A19: 45597 | B19: 123.9 | C19: 670.3 | D19: 4.8194748 | E19: =LN(C19) -> 6.5077254 | F19: 6.5681636 | G19: -0.060438234 | H19: 0.0036527801 | J19: α | K19: 0.05 | L19: Poziom istotności
A20: 45627 | B20: 138.4 | C20: 821.8 | D20: 4.930148 | E20: =LN(C20) -> 6.7114971 | F20: 6.6454511 | G20: 0.066045968 | H20: 0.0043620699
A21: 45658 | B21: 161.2 | C21: 849 | D21: 5.0826458 | E21: =LN(C21) -> 6.7440592 | F21: 6.7519463 | G21: -0.0078870981 | H21: 6.2206317e-05
A22: 45689 | B22: 165.7 | C22: 838.2 | D22: 5.1101789 | E22: =LN(C22) -> 6.7312567 | F22: 6.7711737 | G22: -0.03991699 | H22: 0.0015933661 | J22: A = exp(b0) | K22: =EXP(K11) -> 24.5948
A23: 45717 | B23: 137.8 | C23: 792.9 | D23: 4.9258034 | E23: =LN(C23) -> 6.6756971 | F23: 6.642417 | G23: 0.033280085 | H23: 0.0011075641 | J23: Zmiana Y przy X +1%
A24: 45748 | B24: 149.6 | C24: 832.4 | D24: 5.0079651 | E24: =LN(C24) -> 6.7243131 | F24: 6.6997938 | G24: 0.024519322 | H24: 0.00060119715
A25: 45778 | B25: 101.1 | C25: 600.5 | D25: 4.6161101 | E25: =LN(C25) -> 6.3977626 | F25: 6.4261461 | G25: -0.028383432 | H25: 0.00080561922
A26: 45809 | B26: 107.3 | C26: 630.4 | D26: 4.6756286 | E26: =LN(C26) -> 6.4463545 | F26: 6.4677102 | G26: -0.021355658 | H26: 0.00045606415
A27: 45839 | B27: 169.9 | C27: 908.5 | D27: 5.13521 | E27: =LN(C27) -> 6.8117949 | F27: 6.7886539 | G27: 0.023140958 | H27: 0.00053550396
A28: 45870 | B28: 106.2 | C28: 683.6 | D28: 4.6653241 | E28: =LN(C28) -> 6.527373 | F28: 6.4605141 | G28: 0.06685882 | H28: 0.0044701018
A29: 45901 | B29: 117.3 | C29: 654.3 | D29: 4.7647348 | E29: =LN(C29) -> 6.483566 | F29: 6.5299365 | G29: -0.04637053 | H29: 0.002150226
A30: 45931 | B30: 107 | C30: 654.6 | D30: 4.6728288 | E30: =LN(C30) -> 6.4840244 | F30: 6.465755 | G30: 0.018269386 | H30: 0.00033377047
A31: 45962 | B31: 141.4 | C31: 756.6 | D31: 4.9515928 | E31: =LN(C31) -> 6.6288347 | F31: 6.6604268 | G31: -0.03159206 | H31: 0.00099805827
A32: 45992 | B32: 143.9 | C32: 762 | D32: 4.9691186 | E32: =LN(C32) -> 6.6359466 | F32: 6.6726658 | G32: -0.036719214 | H32: 0.0013483006
A34: X′X (1,Z) | E34: (X′X)⁻¹ | I34: X′Y | K34: z*
J35: 1 | K35: 4.5653893
A36: =COUNT(A9:A32) -> 24 | B36: =SUM(_xlfn.ANCHORARRAY(D9)) -> 115.37572 | E36: {=MINVERSE(A36:B37)} -> 22.798282 | F36: -4.7337411 | J36: 1 | K36: 4.9856593
A37: =B36 -> 115.37572 | B37: =SUMSQ(_xlfn.ANCHORARRAY(D9)) -> 555.66372 | E37: -4.7337411 | F37: 0.98469408 | G37: prognoza punktowa jako mediana | J37: 1 | K37: 4.5829246
G38: łyse oszacowanie Y, takie jakby prognozy | H38: oszcowanie Y z uwzględnieniem tego że mogliśmy isę pomylić jakby bo błąd
A39: Miesiąc | B39: Plan X | C39: z* | D39: μ* | E39: m*(log) | F39: v | G39: Mediana Y | H39: Średnia Y | I39: Dolna 95% | J39: Górna 95% | K39: Realizacja | L39: Błąd średniej
A40: 46023 | B40: 96.1 | C40: =LN(B40) -> 4.5653893 | D40: {=TREND(E9:E32,_xlfn.ANCHORARRAY(D9),C40:C42,1)} -> 6.3907257 | E40: {=$K$14*SQRT(1+MMULT(MMULT(J35:K35,_xlfn.ANCHORARRAY($E$36)),TRANSPOSE(J35:K35)))} -> 0.041517555 | F40: =E40^2 -> 0.0017237074 | G40: =EXP(D40) -> 596.28917 | H40: =EXP(D40+F40) -> 597.31789 | K40: =Realizacje!C7 -> 574.7 | L40: =K40-H40 -> -22.617888
A41: 46054 | B41: 146.3 | C41: =LN(B41) -> 4.9856593 | D41: 6.6842168 | E41: {=$K$14*SQRT(1+MMULT(MMULT(J36:K36,_xlfn.ANCHORARRAY($E$36)),TRANSPOSE(J36:K36)))} -> 0.04101757 | F41: =E41^2 -> 0.0016824411 | G41: =EXP(D41) -> 799.68411 | H41: =EXP(D41+F41) -> 801.03066 | K41: =Realizacje!C8 -> 845.3 | L41: =K41-H41 -> 44.269337
...

Sheet CW
A1: 3. Parabola i test Clarka–Westa
A2: Porównaj M0: Y=β0+β1X+ε oraz M1: Y=β0+β1X+β2X²+ε. M0 otrzymujemy dla β2=0. Prognozy są gotowe.
A3: 1. Wyjaśnij zagnieżdżenie. Na ostatnich współczynnikach M1 oblicz efekt krańcowy przy X=20 i punkt zwrotny.
A4: 2. Wypełnij E:J. e0=y−y*0, e1=y−y*1, korekta=(y*0−y*1)², d=e0²−e1²+korekta.
A5: 3. Oblicz MSE0, MSE1, d̄, s_d, SE(d̄)=s_d/√P, CW i jednostronne p. Poziom istotności 5%, test prawostronny.
A6: H0: dodatkowy składnik kwadratowy nie wnosi informacji prognostycznej. H1: rozszerzenie wnosi informację.
A7: Wersja bez HAC zakłada brak istotnej autokorelacji d. Nie utożsamiaj istotności CW z gwarancją przewagi w każdym przyszłym tygodniu.
A8: Tydzień od | B8: Y realizacja | C8: y* M0 | D8: y* M1 | E8: e0 | F8: e1 | G8: e0² | H8: e1² | I8: Korekta | J8: d
A9: =Modele_CW!A45 -> 45544 | B9: =Modele_CW!D45 -> 347.98 | C9: =Modele_CW!K45 -> 334.67084 | D9: =Modele_CW!L45 -> 355.7521 | L9: P
A10: =Modele_CW!A46 -> 45551 | B10: =Modele_CW!D46 -> 369.7 | C10: =Modele_CW!K46 -> 347.54773 | D10: =Modele_CW!L46 -> 370.34506 | L10: MSE0
A11: =Modele_CW!A47 -> 45558 | B11: =Modele_CW!D47 -> 224.08 | C11: =Modele_CW!K47 -> 253.06706 | D11: =Modele_CW!L47 -> 214.25266 | L11: MSE1
A12: =Modele_CW!A48 -> 45565 | B12: =Modele_CW!D48 -> 383.09 | C12: =Modele_CW!K48 -> 370.65385 | D12: =Modele_CW!L48 -> 391.8114 | L12: d̄
A13: =Modele_CW!A49 -> 45572 | B13: =Modele_CW!D49 -> 410.18 | C13: =Modele_CW!K49 -> 416.00575 | D13: =Modele_CW!L49 -> 417.15224 | L13: s_d
A14: =Modele_CW!A50 -> 45579 | B14: =Modele_CW!D50 -> 342.81 | C14: =Modele_CW!K50 -> 316.37717 | D14: =Modele_CW!L50 -> 331.61301 | L14: SE(d̄)
A15: =Modele_CW!A51 -> 45586 | B15: =Modele_CW!D51 -> 268.15 | C15: =Modele_CW!K51 -> 272.01823 | D15: =Modele_CW!L51 -> 256.8344 | L15: CW
A16: =Modele_CW!A52 -> 45593 | B16: =Modele_CW!D52 -> 299.24 | C16: =Modele_CW!K52 -> 284.99484 | D16: =Modele_CW!L52 -> 282.02807 | L16: p jednostronne
A17: =Modele_CW!A53 -> 45600 | B17: =Modele_CW!D53 -> 332.52 | C17: =Modele_CW!K53 -> 318.9152 | D17: =Modele_CW!L53 -> 334.28926 | L17: α | M17: 0.05
A18: =Modele_CW!A54 -> 45607 | B18: =Modele_CW!D54 -> 339.5 | C18: =Modele_CW!K54 -> 340.55677 | D18: =Modele_CW!L54 -> 360.40822 | L18: wartość krytyczna
A19: =Modele_CW!A55 -> 45614 | B19: =Modele_CW!D55 -> 399.13 | C19: =Modele_CW!K55 -> 401.13243 | D19: =Modele_CW!L55 -> 410.10171 | L19: Decyzja
A20: =Modele_CW!A56 -> 45621 | B20: =Modele_CW!D56 -> 417.93 | C20: =Modele_CW!K56 -> 409.18474 | D20: =Modele_CW!L56 -> 413.94076 | L20: Poprawa MSE
A21: =Modele_CW!A57 -> 45628 | B21: =Modele_CW!D57 -> 323.52 | C21: =Modele_CW!K57 -> 308.08713 | D21: =Modele_CW!L57 -> 317.22122 | L21: r(d_t,d_t−1)
A22: =Modele_CW!A58 -> 45635 | B22: =Modele_CW!D58 -> 421.03 | C22: =Modele_CW!K58 -> 425.80917 | D22: =Modele_CW!L58 -> 419.26239
A23: =Modele_CW!A59 -> 45642 | B23: =Modele_CW!D59 -> 343.67 | C23: =Modele_CW!K59 -> 325.38943 | D23: =Modele_CW!L59 -> 341.1764
A24: =Modele_CW!A60 -> 45649 | B24: =Modele_CW!D60 -> 279.36 | C24: =Modele_CW!K60 -> 284.89344 | D24: =Modele_CW!L60 -> 277.47174 | L24: X do interpretacji | M24: 20
A25: =Modele_CW!A61 -> 45656 | B25: =Modele_CW!D61 -> 425.37 | C25: =Modele_CW!K61 -> 389.71878 | D25: =Modele_CW!L61 -> 404.56969 | L25: Efekt krańcowy
A26: =Modele_CW!A62 -> 45663 | B26: =Modele_CW!D62 -> 271.22 | C26: =Modele_CW!K62 -> 277.99918 | D26: =Modele_CW!L62 -> 265.3108 | L26: Punkt zwrotny X
A27: =Modele_CW!A63 -> 45670 | B27: =Modele_CW!D63 -> 399 | C27: =Modele_CW!K63 -> 397.45281 | D27: =Modele_CW!L63 -> 408.23205
A28: =Modele_CW!A64 -> 45677 | B28: =Modele_CW!D64 -> 410.04 | C28: =Modele_CW!K64 -> 433.25068 | D28: =Modele_CW!L64 -> 420.14121
A29: =Modele_CW!A65 -> 45684 | B29: =Modele_CW!D65 -> 301.68 | C29: =Modele_CW!K65 -> 303.43008 | D29: =Modele_CW!L65 -> 308.96212
A30: =Modele_CW!A66 -> 45691 | B30: =Modele_CW!D66 -> 256.28 | C30: =Modele_CW!K66 -> 269.14226 | D30: =Modele_CW!L66 -> 249.06343
A31: =Modele_CW!A67 -> 45698 | B31: =Modele_CW!D67 -> 280.13 | C31: =Modele_CW!K67 -> 294.76156 | D31: =Modele_CW!L67 -> 295.62807
A32: =Modele_CW!A68 -> 45705 | B32: =Modele_CW!D68 -> 349.86 | C32: =Modele_CW!K68 -> 333.22084 | D32: =Modele_CW!L68 -> 351.5025
A33: =Modele_CW!A69 -> 45712 | B33: =Modele_CW!D69 -> 308.65 | C33: =Modele_CW!K69 -> 293.39652 | D33: =Modele_CW!L69 -> 293.99217
A34: =Modele_CW!A70 -> 45719 | B34: =Modele_CW!D70 -> 409.48 | C34: =Modele_CW!K70 -> 424.41759 | D34: =Modele_CW!L70 -> 418.20795
A35: =Modele_CW!A71 -> 45726 | B35: =Modele_CW!D71 -> 283.75 | C35: =Modele_CW!K71 -> 292.66455 | D35: =Modele_CW!L71 -> 291.66898
A36: =Modele_CW!A72 -> 45733 | B36: =Modele_CW!D72 -> 413.4 | C36: =Modele_CW!K72 -> 418.27072 | D36: =Modele_CW!L72 -> 416.58624
A37: =Modele_CW!A73 -> 45740 | B37: =Modele_CW!D73 -> 413.5 | C37: =Modele_CW!K73 -> 446.73912 | D37: =Modele_CW!L73 -> 420.16942
A38: =Modele_CW!A74 -> 45747 | B38: =Modele_CW!D74 -> 272.88 | C38: =Modele_CW!K74 -> 283.42675 | D38: =Modele_CW!L74 -> 275.37903
... A68: =Modele_CW!A104 -> 45957 | B68: =Modele_CW!D104 -> 409.77 | C68: =Modele_CW!K104 -> 387.7621 | D68: =Modele_CW!L104 -> 404.37228
A71: Wniosek: oddziel wielkość poprawy MSE od istotności statystycznej. Czy niski p potwierdza samą poprawność postaci modelu?
...

Sheet Modele_CW
A1: Historia i odtwarzalne prognozy CW
A2: Dane syntetyczne. M0: Y=β0+β1X+ε. M1: Y=β0+β1X+β2X²+ε. Y: sprzedaż tys. zł, X: reklama tys. zł.
A3: Budżet X jest znany przed początkiem tygodnia. Sprzedaż Y poznajemy dopiero po jego zakończeniu. Daty oznaczają poniedziałek.
A4: Gotowy materiał wejściowy. Pierwsze 36 tygodni: próba początkowa. Następne 60: prognozy h=1, estymacja na rozszerzanej próbie.
A5: Każdy wiersz prognozy wykorzystuje Y tylko do poprzedniego wiersza. Zmiana realizacji bieżącego tygodnia nie może zmienić jego prognozy.
A6: Formuły pomocnicze: S11=Σ(X−średnia X)², S22=Σ(X²−średnia X²)², S12=Σ(X−średnia X)(X²−średnia X²).
A7: M1: b1=(S1y·S22−S2y·S12)/D, b2=(S2y·S11−S1y·S12)/D, D=S11·S22−S12². b0=średnia Y−b1·średnia X−b2·średnia X².
A8: Tydzień od | B8: X reklama | C8: X² | D8: Y sprzedaż | E8: n estymacji | F8: b1 M0 | G8: b0 M0 | H8: b2 M1 | I8: b1 M1 | J8: b0 M1 | K8: y* M0 | L8: y* M1 | M8: Etap
A9: 45292 | B9: 39.6 | C9: =B9^2 -> 1568.16 | D9: 438.74 | M9: estymacja
A10: 45299 | B10: 29.5 | C10: =B10^2 -> 870.25 | D10: 419.88 | M10: estymacja
A11: 45306 | B11: 9.2 | C11: =B11^2 -> 84.64 | D11: 205.4 | M11: estymacja
A12: 45313 | B12: 37 | C12: =B12^2 -> 1369 | D12: 405 | M12: estymacja
A13: 45320 | B13: 15.7 | C13: =B13^2 -> 246.49 | D13: 297.5 | M13: estymacja
A14: 45327 | B14: 32.4 | C14: =B14^2 -> 1049.76 | D14: 403.55 | M14: estymacja
A15: 45334 | B15: 37.4 | C15: =B15^2 -> 1398.76 | D15: 408.11 | M15: estymacja
A16: 45341 | B16: 37.3 | C16: =B16^2 -> 1391.29 | D16: 399.94 | M16: estymacja
A17: 45348 | B17: 31.2 | C17: =B17^2 -> 973.44 | D17: 410.02 | M17: estymacja
A18: 45355 | B18: 20 | C18: =B18^2 -> 400 | D18: 342.29 | M18: estymacja
A19: 45362 | B19: 27.7 | C19: =B19^2 -> 767.29 | D19: 390.7 | M19: estymacja
A20: 45369 | B20: 40.5 | C20: =B20^2 -> 1640.25 | D20: 419.88 | M20: estymacja
... A36: 45481 | B36: 23.5 | C36: =B36^2 -> 552.25 | D36: 371.79 | M36: estymacja
A37: 45488 | B37: 25.6 | C37: =B37^2 -> 655.36 | D37: 384.67 | K37: prognoza z modelu liniowego | L37: prognoza z modelu kwadratowego | M37: estymacja
A38: 45495 | B38: 20 | C38: =B38^2 -> 400 | D38: 335.5 | M38: estymacja
A39: 45502 | B39: 8.9 | C39: =B39^2 -> 79.21 | D39: 205.33 | M39: estymacja
A40: 45509 | B40: 14.2 | C40: =B40^2 -> 201.64 | D40: 278.69 | M40: estymacja
A41: 45516 | B41: 30 | C41: =B41^2 -> 900 | D41: 393.47 | M41: estymacja
A42: 45523 | B42: 18.5 | C42: =B42^2 -> 342.25 | D42: 354.69 | M42: estymacja
A43: 45530 | B43: 37.8 | C43: =B43^2 -> 1428.84 | D43: 416.14 | M43: estymacja
A44: 45537 | B44: 12.3 | C44: =B44^2 -> 151.29 | D44: 259.58 | M44: estymacja
A45: 45544 | B45: 22 | C45: =B45^2 -> 484 | D45: 347.98 | E45: =COUNT($D$9:D44) -> 36 | F45: {=LINEST($D$9:D44,$B$9:B44,1,0)} -> 6.2423862 | G45: 197.33834 | H45: {=LINEST($D$9:D45,$B$9:C45,1,0)} -> -0.22733363 | I45: 17.773531 | J45: 74.763894 | K45: =G45+F45*B45 -> 334.67084 | L45: =J45+I45*B45+H45*C45 -> 355.7521 | M45: ocena
A46: 45551 | B46: 24 | C46: =B46^2 -> 576 | D46: 369.7 | E46: =COUNT($D$9:D45) -> 37 | F46: {=LINEST($D$9:D45,$B$9:B45,1,0)} -> 6.227579 | G46: 198.08584 | H46: {=LINEST($D$9:D46,$B$9:C46,1,0)} -> -0.22712303 | I46: 17.76321 | J46: 74.850883 | K46: =G46+F46*B46 -> 347.54773 | L46: =J46+I46*B46+H46*C46 -> 370.34506 | M46: ocena
A47: 45558 | B47: 8.7 | C47: =B47^2 -> 75.69 | D47: 224.08 | E47: =COUNT($D$9:D46) -> 38 | F47: {=LINEST($D$9:D46,$B$9:B46,1,0)} -> 6.2150541 | G47: 198.99609 | H47: {=LINEST($D$9:D47,$B$9:C47,1,0)} -> -0.2215537 | I47: 17.434597 | J47: 79.34107 | K47: =G47+F47*B47 -> 253.06706 | L47: =J47+I47*B47+H47*C47 -> 214.25266 | M47: ocena
A48: 45565 | B48: 27.7 | C48: =B48^2 -> 767.29 | D48: 383.09 | E48: =COUNT($D$9:D47) -> 39 | F48: {=LINEST($D$9:D47,$B$9:B47,1,0)} -> 6.3361364 | G48: 195.14288 | H48: {=LINEST($D$9:D48,$B$9:C48,1,0)} -> -0.21909822 | I48: 17.307269 | J48: 80.51191 | K48: =G48+F48*B48 -> 370.65385 | L48: =J48+I48*B48+H48*C48 -> 391.8114 | M48: ocena
A49: 45572 | B49: 34.8 | C49: =B49^2 -> 1211.04 | D49: 410.18 | E49: =COUNT($D$9:D48) -> 40 | F49: {=LINEST($D$9:D48,$B$9:B48,1,0)} -> 6.3421405 | G49: 195.29926 | H49: {=LINEST($D$9:D49,$B$9:C49,1,0)} -> -0.2189675 | I49: 17.285199 | J49: 80.805719 | K49: =G49+F49*B49 -> 416.00575 | L49: =J49+I49*B49+H49*C49 -> 417.15224 | M49: ocena
A50: 45579 | B50: 19.1 | C50: =B50^2 -> 364.81 | D50: 342.81 | E50: =COUNT($D$9:D49) -> 41 | F50: {=LINEST($D$9:D49,$B$9:B49,1,0)} -> 6.3297262 | G50: 195.4794 | H50: {=LINEST($D$9:D50,$B$9:C50,1,0)} -> -0.22107772 | I50: 17.372281 | J50: 80.453808 | K50: =G50+F50*B50 -> 316.37717 | L50: =J50+I50*B50+H50*C50 -> 331.61301 | M50: ocena
A51: 45586 | B51: 11.9 | C51: =B51^2 -> 141.61 | D51: 268.15 | E51: =COUNT($D$9:D50) -> 42 | F51: {=LINEST($D$9:D50,$B$9:B50,1,0)} -> 6.2875656 | G51: 197.1962 | H51: {=LINEST($D$9:D51,$B$9:C51,1,0)} -> -0.21878553 | I51: 17.219887 | J51: 82.899957 | K51: =G51+F51*B51 -> 272.01823 | L51: =J51+I51*B51+H51*C51 -> 256.8344 | M51: ocena
A52: 45593 | B52: 14 | C52: =B52^2 -> 196 | D52: 299.24 | E52: =COUNT($D$9:D51) -> 43 | F52: {=LINEST($D$9:D51,$B$9:B51,1,0)} -> 6.2995371 | G52: 196.80132 | H52: {=LINEST($D$9:D52,$B$9:C52,1,0)} -> -0.21794622 | I52: 17.13297 | J52: 84.883949 | K52: =G52+F52*B52 -> 284.99484 | L52: =J52+I52*B52+H52*C52 -> 282.02807 | M52: ocena
A53: 45600 | B53: 19.3 | C53: =B53^2 -> 372.49 | D53: 332.52 | E53: =COUNT($D$9:D52) -> 44 | F53: {=LINEST($D$9:D52,$B$9:B52,1,0)} -> 6.2641576 | G53: 198.01696 | H53: {=LINEST($D$9:D53,$B$9:C53,1,0)} -> -0.21760322 | I53: 17.118181 | J53: 84.963391 | K53: =G53+F53*B53 -> 318.9152 | L53: =J53+I53*B53+H53*C53 -> 334.28926 | M53: ocena
A54: 45607 | B54: 22.7 | C54: =B54^2 -> 515.29 | D54: 339.5 | E54: =COUNT($D$9:D53) -> 45 | F54: {=LINEST($D$9:D53,$B$9:B53,1,0)} -> 6.2468717 | G54: 198.75279 | H54: {=LINEST($D$9:D54,$B$9:C54,1,0)} -> -0.2121946 | I54: 16.858903 | J54: 87.052878 | K54: =G54+F54*B54 -> 340.55677 | L54: =J54+I54*B54+H54*C54 -> 360.40822 | M54: ocena
A55: 45614 | B55: 32.4 | C55: =B55^2 -> 1049.76 | D55: 399.13 | E55: =COUNT($D$9:D54) -> 46 | F55: {=LINEST($D$9:D54,$B$9:B54,1,0)} -> 6.2474116 | G55: 198.7163 | H55: {=LINEST($D$9:D55,$B$9:C55,1,0)} -> -0.21091472 | I55: 16.777128 | J55: 87.932589 | K55: =G55+F55*B55 -> 401.13243 | L55: =J55+I55*B55+H55*C55 -> 410.10171 | M55: ocena
...

Sheet Realizacje
A2: Realizacje poznane po okresie prognozy
A4: Otwórz dopiero po obliczeniu i zapisaniu prognoz. Te wartości nie mogą wejść do estymacji modeli miesięcznych.
A6: Miesiąc | B6: Abonenci (osoby) | C6: Energia (MWh)
A7: 46023 | B7: 2504 | C7: 574.7
A8: 46054 | B8: 2549 | C8: 845.3
A9: 46082 | B9: 2630 | C9: 631.8
A12: Dane syntetyczne. Wyniki są dostępne wyłącznie do oceny ex post, po zakończeniu odpowiedniego miesiąca.
